Workbook

Sheet Read Me
B2: HOTEL BOOKING ANALYSIS — PROJECT WORKBOOK
B4: Prepared using: | C4: Microsoft Excel (data cleaning, formulas, PivotTable-style analysis, charts) + Power BI (interactive dashboard)
B5: Dataset: | C5: Hotel Booking Demand (Antonio, Almeida & Nunes, 2019) — 119,390 real, anonymised hotel bookings for a City Hotel and a Resort Hotel, 2015-2017
B6: Source: | C6: Originally published in the journal 'Data in Brief' (Elsevier). Public CSV mirror used here: rfordatascience/tidytuesday on GitHub
B7: This workbook uses: | C7: A random sample of 2,600 raw bookings (statistically representative of the full 119,390-row dataset) so every formula, calculated column and chart recalculates instantly. All headline business insights in the project report use the FULL 87,230-row cleaned dataset for maximum accuracy — see the accompanying 'hotels_cleaned_full.csv' file and the Insights & Recommendations document.
B9: SHEET GUIDE
B10: Raw Data | C10: Original, unedited sample as downloaded — includes real missing values and duplicate rows, plus audit formulas that detect them.
B11: Cleaning Log | C11: Documents every cleaning decision (missing values, duplicates, invalid rows) with formula-driven before/after counts.
B12: Cleaned Data | C12: The cleaned dataset with 8 new calculated columns (Excel formulas) ready for analysis. Source range for every table below.
B13: KPI Dashboard | C13: Headline KPI cards (Total Bookings, Cancellation Rate, Revenue, ADR, Lead Time, Nights) built with SUMIFS/COUNTIFS/AVERAGEIFS.
B14: Pivot - Cancellation | C14: Cancellation-rate breakdown by hotel type, lead-time bucket, deposit type and market segment, with charts.
B15: Pivot - Revenue | C15: Revenue and ADR by month, hotel type and market segment, with charts.
B16: Pivot - Room Type | C16: Booking volume, revenue and ADR by room type, with charts.
B17: Pivot - LeadTime & Stay | C17: Lead-time distribution and average stay duration by bucket/hotel/customer type/season, with charts.
B18: Pivot - Monthly Trend | C18: Month-by-month booking volume and cancellation-rate seasonality, with trend charts.
B19: Pivot - Customer Segment | C19: Bookings by customer type and market segment, with charts.
B21: HOW TO ADD NATIVE EXCEL PIVOTTABLES (recommended, takes 2 minutes)
B22: 1. Click any cell inside the 'Cleaned Data' table.
B23: 2. Go to Insert > PivotTable > New Worksheet.
B24: 3. Drag a category field (e.g. Reserved Room Type, Market Segment, Arrival Date Month) into ROWS.
B25: 4. Drag 'Booking ID' into VALUES (set to Count) and 'Total Revenue' / 'ADR' into VALUES (set to Sum / Average).
B26: 5. Drag 'Booking Status' into COLUMNS to split Cancelled vs Completed side by side.
B27: 6. Select the PivotTable > Insert > Recommended Charts to auto-generate a matching PivotChart.
B28: This workbook already reproduces the same numbers using SUMIFS / COUNTIFS / AVERAGEIFS formulas (the 'Pivot - ...' sheets),
B29: which shows the underlying formula logic rather than a black-box PivotTable. Adding a couple of native PivotTables on top
B30: satisfies both styles of requirement for a college submission.

Sheet Raw Data
A1: RAW DATA — as downloaded (sample of 2,600 bookings; real missing values & duplicates present) | AL1: RAW DATA AUDIT SUMMARY
AL2: Total rows | AM2: =COUNTA(A4:A2603) -> 2600
A3: booking_id | B3: hotel | C3: is_canceled | D3: lead_time | E3: arrival_date_year | F3: arrival_date_month | G3: arrival_date_week_number | H3: arrival_date_day_of_month | I3: stays_in_weekend_nights | J3: stays_in_week_nights | K3: adults | L3: children | M3: babies | N3: meal | O3: country | P3: market_segment | Q3: distribution_channel | R3: is_repeated_guest | S3: previous_cancellations | T3: previous_bookings_not_canceled | U3: reserved_room_type | V3: assigned_room_type | W3: booking_changes | X3: deposit_type | Y3: agent | Z3: company | AA3: days_in_waiting_list | AB3: customer_type | AC3: adr | AD3: required_car_parking_spaces | AE3: total_of_special_requests | AF3: reservation_status | AG3: reservation_status_date | AH3: Row Key (helper) | AI3: Duplicate Check | AJ3: Missing Values Check | AL3: Duplicate rows found | AM3: =COUNTIF(AI4:AI2603,"Duplicate") -> 257
A4: 1 | B4: Resort Hotel | C4: 0 | D4: 203 | E4: 2016 | F4: December | G4: 49 | H4: 2 | I4: 2 | J4: 5 | K4: 2 | L4: 0 | M4: 0 | N4: BB | O4: GBR | P4: Direct | Q4: Direct | R4: 0 | S4: 0 | T4: 0 | U4: F | V4: F | W4: 4 | X4: No Deposit | Y4: 250 | AA4: 0 | AB4: Transient | AC4: 66.8 | AD4: 0 | AE4: 0 | AF4: Check-Out | AG4: 42713 | AH4: =B4&"|"&C4&"|"&D4&"|"&E4&"|"&F4&"|"&G4&"|"&H4&"|"&I4&"|"&J4&"|"&K4&"|"&L4&"|"&M4&"|"&N4&"|"&O4&"|"&P4&"|"&Q4&"|"&R4&"|"&S4&"|"&T4&"|"&U4&"|"&V4&"|"&W4&"|"&X4&"|"&Y4&"|"&Z4&"|"&AA4&"|"&AB4&"|"&AC4&"|"&AD4&"|"&AE4&"|"&AF4&"|"&AG4 -> Resort Hotel|0|203|2016|December|49|2|2|5|2|0|0|BB|GBR|Direct|Direct|0|0|0|F|F|4|No Deposit|250||0|Transient|66.8|0|0|Check-Out|42713 | AI4: =IF(COUNTIF($AH$4:$AH$2603,AH4)>1,"Duplicate","Unique") -> Unique | AJ4: =IF(COUNTBLANK(B4:AG4)>0,"Missing ("&COUNTBLANK(B4:AG4)&")","Complete") -> Missing (1) | AL4: Rows with missing values | AM4: =COUNTIF(AJ4:AJ2603,"Missing*") -> 2595
A5: 2 | B5: City Hotel | C5: 1 | D5: 82 | E5: 2015 | F5: July | G5: 29 | H5: 16 | I5: 0 | J5: 3 | K5: 2 | L5: 0 | M5: 0 | N5: BB | O5: PRT | P5: Online TA | Q5: TA/TO | R5: 0 | S5: 0 | T5: 0 | U5: A | V5: A | W5: 0 | X5: No Deposit | Y5: 9 | AA5: 0 | AB5: Transient | AC5: 76.5 | AD5: 0 | AE5: 0 | AF5: Canceled | AG5: 42201 | AH5: =B5&"|"&C5&"|"&D5&"|"&E5&"|"&F5&"|"&G5&"|"&H5&"|"&I5&"|"&J5&"|"&K5&"|"&L5&"|"&M5&"|"&N5&"|"&O5&"|"&P5&"|"&Q5&"|"&R5&"|"&S5&"|"&T5&"|"&U5&"|"&V5&"|"&W5&"|"&X5&"|"&Y5&"|"&Z5&"|"&AA5&"|"&AB5&"|"&AC5&"|"&AD5&"|"&AE5&"|"&AF5&"|"&AG5 -> City Hotel|1|82|2015|July|29|16|0|3|2|0|0|BB|PRT|Online TA|TA/TO|0|0|0|A|A|0|No Deposit|9||0|Transient|76.5|0|0|Canceled|42201 | AI5: =IF(COUNTIF($AH$4:$AH$2603,AH5)>1,"Duplicate","Unique") -> Unique | AJ5: =IF(COUNTBLANK(B5:AG5)>0,"Missing ("&COUNTBLANK(B5:AG5)&")","Complete") -> Missing (1) | AL5: Missing - Country | AM5: =COUNTBLANK(O4:O2603) -> 11
A6: 3 | B6: City Hotel | C6: 0 | D6: 25 | E6: 2016 | F6: December | G6: 53 | H6: 27 | I6: 0 | J6: 3 | K6: 3 | L6: 0 | M6: 0 | N6: BB | O6: BRA | P6: Offline TA/TO | Q6: TA/TO | R6: 0 | S6: 0 | T6: 0 | U6: A | V6: K | W6: 2 | X6: No Deposit | Y6: 220 | AA6: 0 | AB6: Transient-Party | AC6: 60 | AD6: 0 | AE6: 1 | AF6: Check-Out | AG6: 42734 | AH6: =B6&"|"&C6&"|"&D6&"|"&E6&"|"&F6&"|"&G6&"|"&H6&"|"&I6&"|"&J6&"|"&K6&"|"&L6&"|"&M6&"|"&N6&"|"&O6&"|"&P6&"|"&Q6&"|"&R6&"|"&S6&"|"&T6&"|"&U6&"|"&V6&"|"&W6&"|"&X6&"|"&Y6&"|"&Z6&"|"&AA6&"|"&AB6&"|"&AC6&"|"&AD6&"|"&AE6&"|"&AF6&"|"&AG6 -> City Hotel|0|25|2016|December|53|27|0|3|3|0|0|BB|BRA|Offline TA/TO|TA/TO|0|0|0|A|K|2|No Deposit|220||0|Transient-Party|60|0|1|Check-Out|42734 | AI6: =IF(COUNTIF($AH$4:$AH$2603,AH6)>1,"Duplicate","Unique") -> Unique | AJ6: =IF(COUNTBLANK(B6:AG6)>0,"Missing ("&COUNTBLANK(B6:AG6)&")","Complete") -> Missing (1) | AL6: Missing - Agent | AM6: =COUNTBLANK(Y4:Y2603) -> 349
A7: 4 | B7: City Hotel | C7: 0 | D7: 1 | E7: 2016 | F7: March | G7: 11 | H7: 9 | I7: 0 | J7: 1 | K7: 1 | L7: 0 | M7: 0 | N7: BB | O7: SWE | P7: Online TA | Q7: TA/TO | R7: 0 | S7: 0 | T7: 0 | U7: A | V7: A | W7: 0 | X7: No Deposit | Y7: 9 | AA7: 0 | AB7: Transient-Party | AC7: 95 | AD7: 0 | AE7: 0 | AF7: Check-Out | AG7: 42439 | AH7: =B7&"|"&C7&"|"&D7&"|"&E7&"|"&F7&"|"&G7&"|"&H7&"|"&I7&"|"&J7&"|"&K7&"|"&L7&"|"&M7&"|"&N7&"|"&O7&"|"&P7&"|"&Q7&"|"&R7&"|"&S7&"|"&T7&"|"&U7&"|"&V7&"|"&W7&"|"&X7&"|"&Y7&"|"&Z7&"|"&AA7&"|"&AB7&"|"&AC7&"|"&AD7&"|"&AE7&"|"&AF7&"|"&AG7 -> City Hotel|0|1|2016|March|11|9|0|1|1|0|0|BB|SWE|Online TA|TA/TO|0|0|0|A|A|0|No Deposit|9||0|Transient-Party|95|0|0|Check-Out|42439 | AI7: =IF(COUNTIF($AH$4:$AH$2603,AH7)>1,"Duplicate","Unique") -> Unique | AJ7: =IF(COUNTBLANK(B7:AG7)>0,"Missing ("&COUNTBLANK(B7:AG7)&")","Complete") -> Missing (1) | AL7: Missing - Company | AM7: =COUNTBLANK(Z4:Z2603) -> 2460
A8: 5 | B8: City Hotel | C8: 0 | D8: 70 | E8: 2017 | F8: April | G8: 16 | H8: 16 | I8: 2 | J8: 2 | K8: 2 | L8: 0 | M8: 0 | N8: SC | O8: GBR | P8: Online TA | Q8: TA/TO | R8: 0 | S8: 0 | T8: 0 | U8: A | V8: A | W8: 0 | X8: No Deposit | Y8: 9 | AA8: 0 | AB8: Transient | AC8: 108 | AD8: 0 | AE8: 0 | AF8: Check-Out | AG8: 42845 | AH8: =B8&"|"&C8&"|"&D8&"|"&E8&"|"&F8&"|"&G8&"|"&H8&"|"&I8&"|"&J8&"|"&K8&"|"&L8&"|"&M8&"|"&N8&"|"&O8&"|"&P8&"|"&Q8&"|"&R8&"|"&S8&"|"&T8&"|"&U8&"|"&V8&"|"&W8&"|"&X8&"|"&Y8&"|"&Z8&"|"&AA8&"|"&AB8&"|"&AC8&"|"&AD8&"|"&AE8&"|"&AF8&"|"&AG8 -> City Hotel|0|70|2017|April|16|16|2|2|2|0|0|SC|GBR|Online TA|TA/TO|0|0|0|A|A|0|No Deposit|9||0|Transient|108|0|0|Check-Out|42845 | AI8: =IF(COUNTIF($AH$4:$AH$2603,AH8)>1,"Duplicate","Unique") -> Unique | AJ8: =IF(COUNTBLANK(B8:AG8)>0,"Missing ("&COUNTBLANK(B8:AG8)&")","Complete") -> Missing (1)
A9: 6 | B9: City Hotel | C9: 0 | D9: 170 | E9: 2017 | F9: April | G9: 17 | H9: 27 | I9: 0 | J9: 3 | K9: 2 | L9: 0 | M9: 0 | N9: BB | O9: DEU | P9: Online TA | Q9: TA/TO | R9: 0 | S9: 0 | T9: 0 | U9: D | V9: D | W9: 0 | X9: No Deposit | Y9: 9 | AA9: 0 | AB9: Transient | AC9: 130.5 | AD9: 0 | AE9: 0 | AF9: Check-Out | AG9: 42855 | AH9: =B9&"|"&C9&"|"&D9&"|"&E9&"|"&F9&"|"&G9&"|"&H9&"|"&I9&"|"&J9&"|"&K9&"|"&L9&"|"&M9&"|"&N9&"|"&O9&"|"&P9&"|"&Q9&"|"&R9&"|"&S9&"|"&T9&"|"&U9&"|"&V9&"|"&W9&"|"&X9&"|"&Y9&"|"&Z9&"|"&AA9&"|"&AB9&"|"&AC9&"|"&AD9&"|"&AE9&"|"&AF9&"|"&AG9 -> City Hotel|0|170|2017|April|17|27|0|3|2|0|0|BB|DEU|Online TA|TA/TO|0|0|0|D|D|0|No Deposit|9||0|Transient|130.5|0|0|Check-Out|42855 | AI9: =IF(COUNTIF($AH$4:$AH$2603,AH9)>1,"Duplicate","Unique") -> Unique | AJ9: =IF(COUNTBLANK(B9:AG9)>0,"Missing ("&COUNTBLANK(B9:AG9)&")","Complete") -> Missing (1)
A10: 7 | B10: City Hotel | C10: 1 | D10: 21 | E10: 2016 | F10: March | G10: 10 | H10: 4 | I10: 0 | J10: 1 | K10: 1 | L10: 0 | M10: 0 | N10: BB | O10: SVN | P10: Online TA | Q10: TA/TO | R10: 0 | S10: 0 | T10: 0 | U10: A | V10: A | W10: 0 | X10: No Deposit | Y10: 9 | AA10: 0 | AB10: Transient-Party | AC10: 85 | AD10: 0 | AE10: 0 | AF10: Canceled | AG10: 42426 | AH10: =B10&"|"&C10&"|"&D10&"|"&E10&"|"&F10&"|"&G10&"|"&H10&"|"&I10&"|"&J10&"|"&K10&"|"&L10&"|"&M10&"|"&N10&"|"&O10&"|"&P10&"|"&Q10&"|"&R10&"|"&S10&"|"&T10&"|"&U10&"|"&V10&"|"&W10&"|"&X10&"|"&Y10&"|"&Z10&"|"&AA10&"|"&AB10&"|"&AC10&"|"&AD10&"|"&AE10&"|"&AF10&"|"&AG10 -> City Hotel|1|21|2016|March|10|4|0|1|1|0|0|BB|SVN|Online TA|TA/TO|0|0|0|A|A|0|No Deposit|9||0|Transient-Party|85|0|0|Canceled|42426 | AI10: =IF(COUNTIF($AH$4:$AH$2603,AH10)>1,"Duplicate","Unique") -> Unique | AJ10: =IF(COUNTBLANK(B10:AG10)>0,"Missing ("&COUNTBLANK(B10:AG10)&")","Complete") -> Missing (1)
A11: 8 | B11: City Hotel | C11: 0 | D11: 102 | E11: 2015 | F11: October | G11: 42 | H11: 16 | I11: 0 | J11: 2 | K11: 2 | L11: 0 | M11: 0 | N11: HB | O11: DEU | P11: Offline TA/TO | Q11: TA/TO | R11: 0 | S11: 0 | T11: 0 | U11: A | V11: D | W11: 0 | X11: No Deposit | Y11: 6 | AA11: 0 | AB11: Transient-Party | AC11: 109 | AD11: 0 | AE11: 0 | AF11: Check-Out | AG11: 42295 | AH11: =B11&"|"&C11&"|"&D11&"|"&E11&"|"&F11&"|"&G11&"|"&H11&"|"&I11&"|"&J11&"|"&K11&"|"&L11&"|"&M11&"|"&N11&"|"&O11&"|"&P11&"|"&Q11&"|"&R11&"|"&S11&"|"&T11&"|"&U11&"|"&V11&"|"&W11&"|"&X11&"|"&Y11&"|"&Z11&"|"&AA11&"|"&AB11&"|"&AC11&"|"&AD11&"|"&AE11&"|"&AF11&"|"&AG11 -> City Hotel|0|102|2015|October|42|16|0|2|2|0|0|HB|DEU|Offline TA/TO|TA/TO|0|0|0|A|D|0|No Deposit|6||0|Transient-Party|109|0|0|Check-Out|42295 | AI11: =IF(COUNTIF($AH$4:$AH$2603,AH11)>1,"Duplicate","Unique") -> Unique | AJ11: =IF(COUNTBLANK(B11:AG11)>0,"Missing ("&COUNTBLANK(B11:AG11)&")","Complete") -> Missing (1)
A12: 9 | B12: Resort Hotel | C12: 0 | D12: 55 | E12: 2016 | F12: November | G12: 47 | H12: 19 | I12: 2 | J12: 5 | K12: 2 | L12: 0 | M12: 0 | N12: HB | O12: GBR | P12: Online TA | Q12: TA/TO | R12: 0 | S12: 0 | T12: 0 | U12: D | V12: D | W12: 1 | X12: No Deposit | Y12: 314 | AA12: 0 | AB12: Transient | AC12: 67.44 | AD12: 0 | AE12: 0 | AF12: Check-Out | AG12: 42700 | AH12: =B12&"|"&C12&"|"&D12&"|"&E12&"|"&F12&"|"&G12&"|"&H12&"|"&I12&"|"&J12&"|"&K12&"|"&L12&"|"&M12&"|"&N12&"|"&O12&"|"&P12&"|"&Q12&"|"&R12&"|"&S12&"|"&T12&"|"&U12&"|"&V12&"|"&W12&"|"&X12&"|"&Y12&"|"&Z12&"|"&AA12&"|"&AB12&"|"&AC12&"|"&AD12&"|"&AE12&"|"&AF12&"|"&AG12 -> Resort Hotel|0|55|2016|November|47|19|2|5|2|0|0|HB|GBR|Online TA|TA/TO|0|0|0|D|D|1|No Deposit|314||0|Transient|67.44|0|0|Check-Out|42700 | AI12: =IF(COUNTIF($AH$4:$AH$2603,AH12)>1,"Duplicate","Unique") -> Unique | AJ12: =IF(COUNTBLANK(B12:AG12)>0,"Missing ("&COUNTBLANK(B12:AG12)&")","Complete") -> Missing (1)
A13: 10 | B13: Resort Hotel | C13: 0 | D13: 222 | E13: 2015 | F13: September | G13: 38 | H13: 14 | I13: 1 | J13: 1 | K13: 2 | L13: 0 | M13: 0 | N13: HB | O13: ESP | P13: Groups | Q13: TA/TO | R13: 0 | S13: 0 | T13: 0 | U13: A | V13: A | W13: 0 | X13: No Deposit | Y13: 68 | AA13: 0 | AB13: Transient | AC13: 80 | AD13: 0 | AE13: 0 | AF13: Check-Out | AG13: 42263 | AH13: =B13&"|"&C13&"|"&D13&"|"&E13&"|"&F13&"|"&G13&"|"&H13&"|"&I13&"|"&J13&"|"&K13&"|"&L13&"|"&M13&"|"&N13&"|"&O13&"|"&P13&"|"&Q13&"|"&R13&"|"&S13&"|"&T13&"|"&U13&"|"&V13&"|"&W13&"|"&X13&"|"&Y13&"|"&Z13&"|"&AA13&"|"&AB13&"|"&AC13&"|"&AD13&"|"&AE13&"|"&AF13&"|"&AG13 -> Resort Hotel|0|222|2015|September|38|14|1|1|2|0|0|HB|ESP|Groups|TA/TO|0|0|0|A|A|0|No Deposit|68||0|Transient|80|0|0|Check-Out|42263 | AI13: =IF(COUNTIF($AH$4:$AH$2603,AH13)>1,"Duplicate","Unique") -> Unique | AJ13: =IF(COUNTBLANK(B13:AG13)>0,"Missing ("&COUNTBLANK(B13:AG13)&")","Complete") -> Missing (1)
A14: 11 | B14: Resort Hotel | C14: 0 | D14: 120 | E14: 2016 | F14: December | G14: 53 | H14: 26 | I14: 1 | J14: 3 | K14: 2 | L14: 0 | M14: 0 | N14: BB | O14: BEL | P14: Online TA | Q14: TA/TO | R14: 0 | S14: 0 | T14: 0 | U14: D | V14: D | W14: 0 | X14: No Deposit | Y14: 240 | AA14: 0 | AB14: Transient-Party | AC14: 54.8 | AD14: 1 | AE14: 3 | AF14: Check-Out | AG14: 42734 | AH14: =B14&"|"&C14&"|"&D14&"|"&E14&"|"&F14&"|"&G14&"|"&H14&"|"&I14&"|"&J14&"|"&K14&"|"&L14&"|"&M14&"|"&N14&"|"&O14&"|"&P14&"|"&Q14&"|"&R14&"|"&S14&"|"&T14&"|"&U14&"|"&V14&"|"&W14&"|"&X14&"|"&Y14&"|"&Z14&"|"&AA14&"|"&AB14&"|"&AC14&"|"&AD14&"|"&AE14&"|"&AF14&"|"&AG14 -> Resort Hotel|0|120|2016|December|53|26|1|3|2|0|0|BB|BEL|Online TA|TA/TO|0|0|0|D|D|0|No Deposit|240||0|Transient-Party|54.8|1|3|Check-Out|42734 | AI14: =IF(COUNTIF($AH$4:$AH$2603,AH14)>1,"Duplicate","Unique") -> Unique | AJ14: =IF(COUNTBLANK(B14:AG14)>0,"Missing ("&COUNTBLANK(B14:AG14)&")","Complete") -> Missing (1)
A15: 12 | B15: City Hotel | C15: 1 | D15: 88 | E15: 2017 | F15: February | G15: 7 | H15: 17 | I15: 0 | J15: 2 | K15: 2 | L15: 0 | M15: 0 | N15: SC | O15: DEU | P15: Online TA | Q15: TA/TO | R15: 0 | S15: 0 | T15: 0 | U15: A | V15: A | W15: 0 | X15: No Deposit | Y15: 9 | AA15: 0 | AB15: Transient | AC15: 79.2 | AD15: 0 | AE15: 0 | AF15: Canceled | AG15: 42699 | AH15: =B15&"|"&C15&"|"&D15&"|"&E15&"|"&F15&"|"&G15&"|"&H15&"|"&I15&"|"&J15&"|"&K15&"|"&L15&"|"&M15&"|"&N15&"|"&O15&"|"&P15&"|"&Q15&"|"&R15&"|"&S15&"|"&T15&"|"&U15&"|"&V15&"|"&W15&"|"&X15&"|"&Y15&"|"&Z15&"|"&AA15&"|"&AB15&"|"&AC15&"|"&AD15&"|"&AE15&"|"&AF15&"|"&AG15 -> City Hotel|1|88|2017|February|7|17|0|2|2|0|0|SC|DEU|Online TA|TA/TO|0|0|0|A|A|0|No Deposit|9||0|Transient|79.2|0|0|Canceled|42699 | AI15: =IF(COUNTIF($AH$4:$AH$2603,AH15)>1,"Duplicate","Unique") -> Unique | AJ15: =IF(COUNTBLANK(B15:AG15)>0,"Missing ("&COUNTBLANK(B15:AG15)&")","Complete") -> Missing (1)
A16: 13 | B16: Resort Hotel | C16: 0 | D16: 79 | E16: 2015 | F16: December | G16: 52 | H16: 24 | I16: 2 | J16: 5 | K16: 2 | L16: 0 | M16: 0 | N16: HB | O16: GBR | P16: Offline TA/TO | Q16: TA/TO | R16: 0 | S16: 0 | T16: 0 | U16: A | V16: A | W16: 0 | X16: No Deposit | Y16: 156 | AA16: 0 | AB16: Transient | AC16: 57.29 | AD16: 0 | AE16: 2 | AF16: Check-Out | AG16: 42369 | AH16: =B16&"|"&C16&"|"&D16&"|"&E16&"|"&F16&"|"&G16&"|"&H16&"|"&I16&"|"&J16&"|"&K16&"|"&L16&"|"&M16&"|"&N16&"|"&O16&"|"&P16&"|"&Q16&"|"&R16&"|"&S16&"|"&T16&"|"&U16&"|"&V16&"|"&W16&"|"&X16&"|"&Y16&"|"&Z16&"|"&AA16&"|"&AB16&"|"&AC16&"|"&AD16&"|"&AE16&"|"&AF16&"|"&AG16 -> Resort Hotel|0|79|2015|December|52|24|2|5|2|0|0|HB|GBR|Offline TA/TO|TA/TO|0|0|0|A|A|0|No Deposit|156||0|Transient|57.29|0|2|Check-Out|42369 | AI16: =IF(COUNTIF($AH$4:$AH$2603,AH16)>1,"Duplicate","Unique") -> Unique | AJ16: =IF(COUNTBLANK(B16:AG16)>0,"Missing ("&COUNTBLANK(B16:AG16)&")","Complete") -> Missing (1)
A17: 14 | B17: City Hotel | C17: 0 | D17: 41 | E17: 2016 | F17: August | G17: 34 | H17: 15 | I17: 1 | J17: 2 | K17: 2 | L17: 0 | M17: 0 | N17: BB | O17: PRT | P17: Offline TA/TO | Q17: TA/TO | R17: 0 | S17: 0 | T17: 0 | U17: A | V17: A | W17: 0 | X17: No Deposit | Y17: 28 | AA17: 0 | AB17: Transient | AC17: 76.5 | AD17: 0 | AE17: 0 | AF17: Check-Out | AG17: 42600 | AH17: =B17&"|"&C17&"|"&D17&"|"&E17&"|"&F17&"|"&G17&"|"&H17&"|"&I17&"|"&J17&"|"&K17&"|"&L17&"|"&M17&"|"&N17&"|"&O17&"|"&P17&"|"&Q17&"|"&R17&"|"&S17&"|"&T17&"|"&U17&"|"&V17&"|"&W17&"|"&X17&"|"&Y17&"|"&Z17&"|"&AA17&"|"&AB17&"|"&AC17&"|"&AD17&"|"&AE17&"|"&AF17&"|"&AG17 -> City Hotel|0|41|2016|August|34|15|1|2|2|0|0|BB|PRT|Offline TA/TO|TA/TO|0|0|0|A|A|0|No Deposit|28||0|Transient|76.5|0|0|Check-Out|42600 | AI17: =IF(COUNTIF($AH$4:$AH$2603,AH17)>1,"Duplicate","Unique") -> Unique | AJ17: =IF(COUNTBLANK(B17:AG17)>0,"Missing ("&COUNTBLANK(B17:AG17)&")","Complete") -> Missing (1)
A18: 15 | B18: City Hotel | C18: 1 | D18: 239 | E18: 2015 | F18: October | G18: 42 | H18: 17 | I18: 0 | J18: 1 | K18: 2 | L18: 0 | M18: 0 | N18: BB | O18: PRT | P18: Groups | Q18: TA/TO | R18: 0 | S18: 1 | T18: 0 | U18: A | V18: A | W18: 0 | X18: Non Refund | Y18: 1 | AA18: 0 | AB18: Transient | AC18: 60 | AD18: 0 | AE18: 0 | AF18: Canceled | AG18: 42233 | AH18: =B18&"|"&C18&"|"&D18&"|"&E18&"|"&F18&"|"&G18&"|"&H18&"|"&I18&"|"&J18&"|"&K18&"|"&L18&"|"&M18&"|"&N18&"|"&O18&"|"&P18&"|"&Q18&"|"&R18&"|"&S18&"|"&T18&"|"&U18&"|"&V18&"|"&W18&"|"&X18&"|"&Y18&"|"&Z18&"|"&AA18&"|"&AB18&"|"&AC18&"|"&AD18&"|"&AE18&"|"&AF18&"|"&AG18 -> City Hotel|1|239|2015|October|42|17|0|1|2|0|0|BB|PRT|Groups|TA/TO|0|1|0|A|A|0|Non Refund|1||0|Transient|60|0|0|Canceled|42233 | AI18: =IF(COUNTIF($AH$4:$AH$2603,AH18)>1,"Duplicate","Unique") -> Unique | AJ18: =IF(COUNTBLANK(B18:AG18)>0,"Missing ("&COUNTBLANK(B18:AG18)&")","Complete") -> Missing (1)
A19: 16 | B19: Resort Hotel | C19: 0 | D19: 23 | E19: 2017 | F19: April | G19: 16 | H19: 20 | I19: 0 | J19: 2 | K19: 2 | L19: 0 | M19: 0 | N19: BB | O19: GBR | P19: Groups | Q19: Direct | R19: 0 | S19: 0 | T19: 0 | U19: A | V19: A | W19: 0 | X19: No Deposit | AA19: 0 | AB19: Transient-Party | AC19: 99 | AD19: 1 | AE19: 0 | AF19: Check-Out | AG19: 42847 | AH19: =B19&"|"&C19&"|"&D19&"|"&E19&"|"&F19&"|"&G19&"|"&H19&"|"&I19&"|"&J19&"|"&K19&"|"&L19&"|"&M19&"|"&N19&"|"&O19&"|"&P19&"|"&Q19&"|"&R19&"|"&S19&"|"&T19&"|"&U19&"|"&V19&"|"&W19&"|"&X19&"|"&Y19&"|"&Z19&"|"&AA19&"|"&AB19&"|"&AC19&"|"&AD19&"|"&AE19&"|"&AF19&"|"&AG19 -> Resort Hotel|0|23|2017|April|16|20|0|2|2|0|0|BB|GBR|Groups|Direct|0|0|0|A|A|0|No Deposit|||0|Transient-Party|99|1|0|Check-Out|42847 | AI19: =IF(COUNTIF($AH$4:$AH$2603,AH19)>1,"Duplicate","Unique") -> Unique | AJ19: =IF(COUNTBLANK(B19:AG19)>0,"Missing ("&COUNTBLANK(B19:AG19)&")","Complete") -> Missing (2)
A20: 17 | B20: Resort Hotel | C20: 0 | D20: 34 | E20: 2016 | F20: December | G20: 50 | H20: 9 | I20: 0 | J20: 1 | K20: 2 | L20: 0 | M20: 0 | N20: BB | O20: PRT | P20: Online TA | Q20: TA/TO | R20: 0 | S20: 0 | T20: 0 | U20: A | V20: D | W20: 0 | X20: No Deposit | Y20: 240 | AA20: 0 | AB20: Transient | AC20: 48 | AD20: 0 | AE20: 1 | AF20: Check-Out | AG20: 42714 | AH20: =B20&"|"&C20&"|"&D20&"|"&E20&"|"&F20&"|"&G20&"|"&H20&"|"&I20&"|"&J20&"|"&K20&"|"&L20&"|"&M20&"|"&N20&"|"&O20&"|"&P20&"|"&Q20&"|"&R20&"|"&S20&"|"&T20&"|"&U20&"|"&V20&"|"&W20&"|"&X20&"|"&Y20&"|"&Z20&"|"&AA20&"|"&AB20&"|"&AC20&"|"&AD20&"|"&AE20&"|"&AF20&"|"&AG20 -> Resort Hotel|0|34|2016|December|50|9|0|1|2|0|0|BB|PRT|Online TA|TA/TO|0|0|0|A|D|0|No Deposit|240||0|Transient|48|0|1|Check-Out|42714 | AI20: =IF(COUNTIF($AH$4:$AH$2603,AH20)>1,"Duplicate","Unique") -> Unique | AJ20: =IF(COUNTBLANK(B20:AG20)>0,"Missing ("&COUNTBLANK(B20:AG20)&")","Complete") -> Missing (1)
A21: 18 | B21: City Hotel | C21: 1 | D21: 38 | E21: 2016 | F21: May | G21: 19 | H21: 6 | I21: 2 | J21: 3 | K21: 2 | L21: 1 | M21: 0 | N21: HB | O21: FRA | P21: Online TA | Q21: TA/TO | R21: 0 | S21: 0 | T21: 0 | U21: A | V21: A | W21: 0 | X21: No Deposit | Y21: 9 | AA21: 0 | AB21: Transient | AC21: 149.68 | AD21: 0 | AE21: 0 | AF21: Canceled | AG21: 42491 | AH21: =B21&"|"&C21&"|"&D21&"|"&E21&"|"&F21&"|"&G21&"|"&H21&"|"&I21&"|"&J21&"|"&K21&"|"&L21&"|"&M21&"|"&N21&"|"&O21&"|"&P21&"|"&Q21&"|"&R21&"|"&S21&"|"&T21&"|"&U21&"|"&V21&"|"&W21&"|"&X21&"|"&Y21&"|"&Z21&"|"&AA21&"|"&AB21&"|"&AC21&"|"&AD21&"|"&AE21&"|"&AF21&"|"&AG21 -> City Hotel|1|38|2016|May|19|6|2|3|2|1|0|HB|FRA|Online TA|TA/TO|0|0|0|A|A|0|No Deposit|9||0|Transient|149.68|0|0|Canceled|42491 | AI21: =IF(COUNTIF($AH$4:$AH$2603,AH21)>1,"Duplicate","Unique") -> Unique | AJ21: =IF(COUNTBLANK(B21:AG21)>0,"Missing ("&COUNTBLANK(B21:AG21)&")","Complete") -> Missing (1)
A22: 19 | B22: City Hotel | C22: 0 | D22: 160 | E22: 2017 | F22: July | G22: 28 | H22: 15 | I22: 2 | J22: 5 | K22: 2 | L22: 0 | M22: 0 | N22: BB | O22: FRA | P22: Online TA | Q22: TA/TO | R22: 0 | S22: 0 | T22: 0 | U22: A | V22: A | W22: 0 | X22: No Deposit | Y22: 7 | AA22: 0 | AB22: Transient | AC22: 78.35 | AD22: 0 | AE22: 1 | AF22: Check-Out | AG22: 42938 | AH22: =B22&"|"&C22&"|"&D22&"|"&E22&"|"&F22&"|"&G22&"|"&H22&"|"&I22&"|"&J22&"|"&K22&"|"&L22&"|"&M22&"|"&N22&"|"&O22&"|"&P22&"|"&Q22&"|"&R22&"|"&S22&"|"&T22&"|"&U22&"|"&V22&"|"&W22&"|"&X22&"|"&Y22&"|"&Z22&"|"&AA22&"|"&AB22&"|"&AC22&"|"&AD22&"|"&AE22&"|"&AF22&"|"&AG22 -> City Hotel|0|160|2017|July|28|15|2|5|2|0|0|BB|FRA|Online TA|TA/TO|0|0|0|A|A|0|No Deposit|7||0|Transient|78.35|0|1|Check-Out|42938 | AI22: =IF(COUNTIF($AH$4:$AH$2603,AH22)>1,"Duplicate","Unique") -> Unique | AJ22: =IF(COUNTBLANK(B22:AG22)>0,"Missing ("&COUNTBLANK(B22:AG22)&")","Complete") -> Missing (1)
A23: 20 | B23: Resort Hotel | C23: 0 | D23: 32 | E23: 2016 | F23: October | G23: 44 | H23: 27 | I23: 2 | J23: 5 | K23: 2 | L23: 0 | M23: 0 | N23: BB | O23: FRA | P23: Direct | Q23: Direct | R23: 0 | S23: 0 | T23: 0 | U23: F | V23: F | W23: 0 | X23: No Deposit | Y23: 250 | AA23: 0 | AB23: Transient | AC23: 91.85 | AD23: 1 | AE23: 0 | AF23: Check-Out | AG23: 42677 | AH23: =B23&"|"&C23&"|"&D23&"|"&E23&"|"&F23&"|"&G23&"|"&H23&"|"&I23&"|"&J23&"|"&K23&"|"&L23&"|"&M23&"|"&N23&"|"&O23&"|"&P23&"|"&Q23&"|"&R23&"|"&S23&"|"&T23&"|"&U23&"|"&V23&"|"&W23&"|"&X23&"|"&Y23&"|"&Z23&"|"&AA23&"|"&AB23&"|"&AC23&"|"&AD23&"|"&AE23&"|"&AF23&"|"&AG23 -> Resort Hotel|0|32|2016|October|44|27|2|5|2|0|0|BB|FRA|Direct|Direct|0|0|0|F|F|0|No Deposit|250||0|Transient|91.85|1|0|Check-Out|42677 | AI23: =IF(COUNTIF($AH$4:$AH$2603,AH23)>1,"Duplicate","Unique") -> Unique | AJ23: =IF(COUNTBLANK(B23:AG23)>0,"Missing ("&COUNTBLANK(B23:AG23)&")","Complete") -> Missing (1)
A24: 21 | B24: Resort Hotel | C24: 0 | D24: 56 | E24: 2016 | F24: March | G24: 14 | H24: 29 | I24: 0 | J24: 4 | K24: 2 | L24: 0 | M24: 0 | N24: BB | O24: PRT | P24: Online TA | Q24: TA/TO | R24: 0 | S24: 0 | T24: 0 | U24: A | V24: A | W24: 0 | X24: No Deposit | Y24: 240 | AA24: 0 | AB24: Transient | AC24: 58 | AD24: 1 | AE24: 1 | AF24: Check-Out | AG24: 42462 | AH24: =B24&"|"&C24&"|"&D24&"|"&E24&"|"&F24&"|"&G24&"|"&H24&"|"&I24&"|"&J24&"|"&K24&"|"&L24&"|"&M24&"|"&N24&"|"&O24&"|"&P24&"|"&Q24&"|"&R24&"|"&S24&"|"&T24&"|"&U24&"|"&V24&"|"&W24&"|"&X24&"|"&Y24&"|"&Z24&"|"&AA24&"|"&AB24&"|"&AC24&"|"&AD24&"|"&AE24&"|"&AF24&"|"&AG24 -> Resort Hotel|0|56|2016|March|14|29|0|4|2|0|0|BB|PRT|Online TA|TA/TO|0|0|0|A|A|0|No Deposit|240||0|Transient|58|1|1|Check-Out|42462 | AI24: =IF(COUNTIF($AH$4:$AH$2603,AH24)>1,"Duplicate","Unique") -> Unique | AJ24: =IF(COUNTBLANK(B24:AG24)>0,"Missing ("&COUNTBLANK(B24:AG24)&")","Complete") -> Missing (1)
A25: 22 | B25: City Hotel | C25: 1 | D25: 97 | E25: 2015 | F25: October | G25: 41 | H25: 5 | I25: 1 | J25: 3 | K25: 1 | L25: 0 | M25: 0 | N25: BB | O25: PRT | P25: Groups | Q25: TA/TO | R25: 0 | S25: 0 | T25: 0 | U25: A | V25: A | W25: 0 | X25: Non Refund | Y25: 29 | AA25: 0 | AB25: Transient | AC25: 140 | AD25: 0 | AE25: 0 | AF25: Canceled | AG25: 42188 | AH25: =B25&"|"&C25&"|"&D25&"|"&E25&"|"&F25&"|"&G25&"|"&H25&"|"&I25&"|"&J25&"|"&K25&"|"&L25&"|"&M25&"|"&N25&"|"&O25&"|"&P25&"|"&Q25&"|"&R25&"|"&S25&"|"&T25&"|"&U25&"|"&V25&"|"&W25&"|"&X25&"|"&Y25&"|"&Z25&"|"&AA25&"|"&AB25&"|"&AC25&"|"&AD25&"|"&AE25&"|"&AF25&"|"&AG25 -> City Hotel|1|97|2015|October|41|5|1|3|1|0|0|BB|PRT|Groups|TA/TO|0|0|0|A|A|0|Non Refund|29||0|Transient|140|0|0|Canceled|42188 | AI25: =IF(COUNTIF($AH$4:$AH$2603,AH25)>1,"Duplicate","Unique") -> Duplicate | AJ25: =IF(COUNTBLANK(B25:AG25)>0,"Missing ("&COUNTBLANK(B25:AG25)&")","Complete") -> Missing (1)
A26: 23 | B26: Resort Hotel | C26: 0 | D26: 85 | E26: 2017 | F26: April | G26: 16 | H26: 19 | I26: 1 | J26: 4 | K26: 2 | L26: 0 | M26: 0 | N26: BB | O26: USA | P26: Direct | Q26: Direct | R26: 0 | S26: 0 | T26: 0 | U26: E | V26: E | W26: 2 | X26: No Deposit | AA26: 0 | AB26: Transient-Party | AC26: 74.6 | AD26: 0 | AE26: 1 | AF26: Check-Out | AG26: 42849 | AH26: =B26&"|"&C26&"|"&D26&"|"&E26&"|"&F26&"|"&G26&"|"&H26&"|"&I26&"|"&J26&"|"&K26&"|"&L26&"|"&M26&"|"&N26&"|"&O26&"|"&P26&"|"&Q26&"|"&R26&"|"&S26&"|"&T26&"|"&U26&"|"&V26&"|"&W26&"|"&X26&"|"&Y26&"|"&Z26&"|"&AA26&"|"&AB26&"|"&AC26&"|"&AD26&"|"&AE26&"|"&AF26&"|"&AG26 -> Resort Hotel|0|85|2017|April|16|19|1|4|2|0|0|BB|USA|Direct|Direct|0|0|0|E|E|2|No Deposit|||0|Transient-Party|74.6|0|1|Check-Out|42849 | AI26: =IF(COUNTIF($AH$4:$AH$2603,AH26)>1,"Duplicate","Unique") -> Unique | AJ26: =IF(COUNTBLANK(B26:AG26)>0,"Missing ("&COUNTBLANK(B26:AG26)&")","Complete") -> Missing (2)
A27: 24 | B27: City Hotel | C27: 0 | D27: 278 | E27: 2017 | F27: July | G27: 30 | H27: 26 | I27: 0 | J27: 4 | K27: 3 | L27: 0 | M27: 0 | N27: BB | O27: DEU | P27: Online TA | Q27: TA/TO | R27: 0 | S27: 0 | T27: 0 | U27: D | V27: D | W27: 0 | X27: No Deposit | Y27: 9 | AA27: 0 | AB27: Transient | AC27: 165.6 | AD27: 0 | AE27: 2 | AF27: Check-Out | AG27: 42946 | AH27: =B27&"|"&C27&"|"&D27&"|"&E27&"|"&F27&"|"&G27&"|"&H27&"|"&I27&"|"&J27&"|"&K27&"|"&L27&"|"&M27&"|"&N27&"|"&O27&"|"&P27&"|"&Q27&"|"&R27&"|"&S27&"|"&T27&"|"&U27&"|"&V27&"|"&W27&"|"&X27&"|"&Y27&"|"&Z27&"|"&AA27&"|"&AB27&"|"&AC27&"|"&AD27&"|"&AE27&"|"&AF27&"|"&AG27 -> City Hotel|0|278|2017|July|30|26|0|4|3|0|0|BB|DEU|Online TA|TA/TO|0|0|0|D|D|0|No Deposit|9||0|Transient|165.6|0|2|Check-Out|42946 | AI27: =IF(COUNTIF($AH$4:$AH$2603,AH27)>1,"Duplicate","Unique") -> Unique | AJ27: =IF(COUNTBLANK(B27:AG27)>0,"Missing ("&COUNTBLANK(B27:AG27)&")","Complete") -> Missing (1)
A28: 25 | B28: City Hotel | C28: 1 | D28: 175 | E28: 2016 | F28: August | G28: 33 | H28: 10 | I28: 0 | J28: 4 | K28: 2 | L28: 0 | M28: 0 | N28: BB | O28: GBR | P28: Online TA | Q28: TA/TO | R28: 0 | S28: 0 | T28: 0 | U28: A | V28: A | W28: 0 | X28: No Deposit | Y28: 9 | AA28: 0 | AB28: Transient | AC28: 99.45 | AD28: 0 | AE28: 0 | AF28: Canceled | AG28: 42430 | AH28: =B28&"|"&C28&"|"&D28&"|"&E28&"|"&F28&"|"&G28&"|"&H28&"|"&I28&"|"&J28&"|"&K28&"|"&L28&"|"&M28&"|"&N28&"|"&O28&"|"&P28&"|"&Q28&"|"&R28&"|"&S28&"|"&T28&"|"&U28&"|"&V28&"|"&W28&"|"&X28&"|"&Y28&"|"&Z28&"|"&AA28&"|"&AB28&"|"&AC28&"|"&AD28&"|"&AE28&"|"&AF28&"|"&AG28 -> City Hotel|1|175|2016|August|33|10|0|4|2|0|0|BB|GBR|Online TA|TA/TO|0|0|0|A|A|0|No Deposit|9||0|Transient|99.45|0|0|Canceled|42430 | AI28: =IF(COUNTIF($AH$4:$AH$2603,AH28)>1,"Duplicate","Unique") -> Unique | AJ28: =IF(COUNTBLANK(B28:AG28)>0,"Missing ("&COUNTBLANK(B28:AG28)&")","Complete") -> Missing (1)
A29: 26 | B29: City Hotel | C29: 1 | D29: 26 | E29: 2017 | F29: May | G29: 21 | H29: 22 | I29: 1 | J29: 1 | K29: 2 | L29: 0 | M29: 0 | N29: BB | O29: PRT | P29: Offline TA/TO | Q29: TA/TO | R29: 0 | S29: 0 | T29: 0 | U29: A | V29: A | W29: 0 | X29: Non Refund | Y29: 3 | AA29: 0 | AB29: Transient | AC29: 128 | AD29: 0 | AE29: 0 | AF29: Canceled | AG29: 42851 | AH29: =B29&"|"&C29&"|"&D29&"|"&E29&"|"&F29&"|"&G29&"|"&H29&"|"&I29&"|"&J29&"|"&K29&"|"&L29&"|"&M29&"|"&N29&"|"&O29&"|"&P29&"|"&Q29&"|"&R29&"|"&S29&"|"&T29&"|"&U29&"|"&V29&"|"&W29&"|"&X29&"|"&Y29&"|"&Z29&"|"&AA29&"|"&AB29&"|"&AC29&"|"&AD29&"|"&AE29&"|"&AF29&"|"&AG29 -> City Hotel|1|26|2017|May|21|22|1|1|2|0|0|BB|PRT|Offline TA/TO|TA/TO|0|0|0|A|A|0|Non Refund|3||0|Transient|128|0|0|Canceled|42851 | AI29: =IF(COUNTIF($AH$4:$AH$2603,AH29)>1,"Duplicate","Unique") -> Unique | AJ29: =IF(COUNTBLANK(B29:AG29)>0,"Missing ("&COUNTBLANK(B29:AG29)&")","Complete") -> Missing (1)
A30: 27 | B30: City Hotel | C30: 1 | D30: 360 | E30: 2015 | F30: October | G30: 42 | H30: 12 | I30: 1 | J30: 1 | K30: 2 | L30: 0 | M30: 0 | N30: BB | O30: PRT | P30: Groups | Q30: TA/TO | R30: 0 | S30: 1 | T30: 0 | U30: A | V30: A | W30: 0 | X30: Non Refund | Y30: 1 | AA30: 0 | AB30: Contract | AC30: 62 | AD30: 0 | AE30: 0 | AF30: Canceled | AG30: 42005 | AH30: =B30&"|"&C30&"|"&D30&"|"&E30&"|"&F30&"|"&G30&"|"&H30&"|"&I30&"|"&J30&"|"&K30&"|"&L30&"|"&M30&"|"&N30&"|"&O30&"|"&P30&"|"&Q30&"|"&R30&"|"&S30&"|"&T30&"|"&U30&"|"&V30&"|"&W30&"|"&X30&"|"&Y30&"|"&Z30&"|"&AA30&"|"&AB30&"|"&AC30&"|"&AD30&"|"&AE30&"|"&AF30&"|"&AG30 -> City Hotel|1|360|2015|October|42|12|1|1|2|0|0|BB|PRT|Groups|TA/TO|0|1|0|A|A|0|Non Refund|1||0|Contract|62|0|0|Canceled|42005 | AI30: =IF(COUNTIF($AH$4:$AH$2603,AH30)>1,"Duplicate","Unique") -> Unique | AJ30: =IF(COUNTBLANK(B30:AG30)>0,"Missing ("&COUNTBLANK(B30:AG30)&")","Complete") -> Missing (1)
A31: 28 | B31: Resort Hotel | C31: 1 | D31: 378 | E31: 2016 | F31: November | G31: 45 | H31: 1 | I31: 0 | J31: 2 | K31: 2 | L31: 0 | M31: 0 | N31: BB | O31: PRT | P31: Groups | Q31: TA/TO | R31: 0 | S31: 0 | T31: 0 | U31: A | V31: A | W31: 0 | X31: Non Refund | Y31: 248 | AA31: 0 | AB31: Transient | AC31: 46 | AD31: 0 | AE31: 0 | AF31: Canceled | AG31: 42661 | AH31: =B31&"|"&C31&"|"&D31&"|"&E31&"|"&F31&"|"&G31&"|"&H31&"|"&I31&"|"&J31&"|"&K31&"|"&L31&"|"&M31&"|"&N31&"|"&O31&"|"&P31&"|"&Q31&"|"&R31&"|"&S31&"|"&T31&"|"&U31&"|"&V31&"|"&W31&"|"&X31&"|"&Y31&"|"&Z31&"|"&AA31&"|"&AB31&"|"&AC31&"|"&AD31&"|"&AE31&"|"&AF31&"|"&AG31 -> Resort Hotel|1|378|2016|November|45|1|0|2|2|0|0|BB|PRT|Groups|TA/TO|0|0|0|A|A|0|Non Refund|248||0|Transient|46|0|0|Canceled|42661 | AI31: =IF(COUNTIF($AH$4:$AH$2603,AH31)>1,"Duplicate","Unique") -> Unique | AJ31: =IF(COUNTBLANK(B31:AG31)>0,"Missing ("&COUNTBLANK(B31:AG31)&")","Complete") -> Missing (1)
A32: 29 | B32: City Hotel | C32: 0 | D32: 32 | E32: 2016 | F32: January | G32: 5 | H32: 24 | I32: 2 | J32: 1 | K32: 2 | L32: 0 | M32: 0 | N32: BB | O32: ARG | P32: Corporate | Q32: Corporate | R32: 0 | S32: 0 | T32: 0 | U32: A | V32: A | W32: 1 | X32: No Deposit | Y32: 38 | AA32: 15 | AB32: Transient-Party | AC32: 64 | AD32: 0 | AE32: 0 | AF32: Check-Out | AG32: 42396 | AH32: =B32&"|"&C32&"|"&D32&"|"&E32&"|"&F32&"|"&G32&"|"&H32&"|"&I32&"|"&J32&"|"&K32&"|"&L32&"|"&M32&"|"&N32&"|"&O32&"|"&P32&"|"&Q32&"|"&R32&"|"&S32&"|"&T32&"|"&U32&"|"&V32&"|"&W32&"|"&X32&"|"&Y32&"|"&Z32&"|"&AA32&"|"&AB32&"|"&AC32&"|"&AD32&"|"&AE32&"|"&AF32&"|"&AG32 -> City Hotel|0|32|2016|January|5|24|2|1|2|0|0|BB|ARG|Corporate|Corporate|0|0|0|A|A|1|No Deposit|38||15|Transient-Party|64|0|0|Check-Out|42396 | AI32: =IF(COUNTIF($AH$4:$AH$2603,AH32)>1,"Duplicate","Unique") -> Unique | AJ32: =IF(COUNTBLANK(B32:AG32)>0,"Missing ("&COUNTBLANK(B32:AG32)&")","Complete") -> Missing (1)
A33: 30 | B33: Resort Hotel | C33: 0 | D33: 165 | E33: 2015 | F33: December | G33: 53 | H33: 30 | I33: 0 | J33: 4 | K33: 1 | L33: 0 | M33: 0 | N33: Undefined | O33: PRT | P33: Groups | Q33: TA/TO | R33: 0 | S33: 0 | T33: 0 | U33: A | V33: A | W33: 0 | X33: No Deposit | Y33: 308 | AA33: 122 | AB33: Transient-Party | AC33: 0 | AD33: 0 | AE33: 0 | AF33: Check-Out | AG33: 42372 | AH33: =B33&"|"&C33&"|"&D33&"|"&E33&"|"&F33&"|"&G33&"|"&H33&"|"&I33&"|"&J33&"|"&K33&"|"&L33&"|"&M33&"|"&N33&"|"&O33&"|"&P33&"|"&Q33&"|"&R33&"|"&S33&"|"&T33&"|"&U33&"|"&V33&"|"&W33&"|"&X33&"|"&Y33&"|"&Z33&"|"&AA33&"|"&AB33&"|"&AC33&"|"&AD33&"|"&AE33&"|"&AF33&"|"&AG33 -> Resort Hotel|0|165|2015|December|53|30|0|4|1|0|0|Undefined|PRT|Groups|TA/TO|0|0|0|A|A|0|No Deposit|308||122|Transient-Party|0|0|0|Check-Out|42372 | AI33: =IF(COUNTIF($AH$4:$AH$2603,AH33)>1,"Duplicate","Unique") -> Unique | AJ33: =IF(COUNTBLANK(B33:AG33)>0,"Missing ("&COUNTBLANK(B33:AG33)&")","Complete") -> Missing (1)
A34: 31 | B34: City Hotel | C34: 0 | D34: 4 | E34: 2015 | F34: August | G34: 35 | H34: 25 | I34: 0 | J34: 4 | K34: 2 | L34: 0 | M34: 0 | N34: BB | O34: PRT | P34: Groups | Q34: TA/TO | R34: 0 | S34: 0 | T34: 0 | U34: A | V34: A | W34: 0 | X34: No Deposit | Y34: 1 | AA34: 0 | AB34: Transient-Party | AC34: 62 | AD34: 0 | AE34: 0 | AF34: Check-Out | AG34: 42245 | AH34: =B34&"|"&C34&"|"&D34&"|"&E34&"|"&F34&"|"&G34&"|"&H34&"|"&I34&"|"&J34&"|"&K34&"|"&L34&"|"&M34&"|"&N34&"|"&O34&"|"&P34&"|"&Q34&"|"&R34&"|"&S34&"|"&T34&"|"&U34&"|"&V34&"|"&W34&"|"&X34&"|"&Y34&"|"&Z34&"|"&AA34&"|"&AB34&"|"&AC34&"|"&AD34&"|"&AE34&"|"&AF34&"|"&AG34 -> City Hotel|0|4|2015|August|35|25|0|4|2|0|0|BB|PRT|Groups|TA/TO|0|0|0|A|A|0|No Deposit|1||0|Transient-Party|62|0|0|Check-Out|42245 | AI34: =IF(COUNTIF($AH$4:$AH$2603,AH34)>1,"Duplicate","Unique") -> Unique | AJ34: =IF(COUNTBLANK(B34:AG34)>0,"Missing ("&COUNTBLANK(B34:AG34)&")","Complete") -> Missing (1)
A35: 32 | B35: City Hotel | C35: 1 | D35: 179 | E35: 2016 | F35: July | G35: 27 | H35: 1 | I35: 0 | J35: 2 | K35: 2 | L35: 0 | M35: 0 | N35: BB | O35: PRT | P35: Groups | Q35: TA/TO | R35: 0 | S35: 0 | T35: 0 | U35: A | V35: A | W35: 0 | X35: Non Refund | Y35: 1 | AA35: 0 | AB35: Transient | AC35: 65 | AD35: 0 | AE35: 0 | AF35: Canceled | AG35: 42500 | AH35: =B35&"|"&C35&"|"&D35&"|"&E35&"|"&F35&"|"&G35&"|"&H35&"|"&I35&"|"&J35&"|"&K35&"|"&L35&"|"&M35&"|"&N35&"|"&O35&"|"&P35&"|"&Q35&"|"&R35&"|"&S35&"|"&T35&"|"&U35&"|"&V35&"|"&W35&"|"&X35&"|"&Y35&"|"&Z35&"|"&AA35&"|"&AB35&"|"&AC35&"|"&AD35&"|"&AE35&"|"&AF35&"|"&AG35 -> City Hotel|1|179|2016|July|27|1|0|2|2|0|0|BB|PRT|Groups|TA/TO|0|0|0|A|A|0|Non Refund|1||0|Transient|65|0|0|Canceled|42500 | AI35: =IF(COUNTIF($AH$4:$AH$2603,AH35)>1,"Duplicate","Unique") -> Unique | AJ35: =IF(COUNTBLANK(B35:AG35)>0,"Missing ("&COUNTBLANK(B35:AG35)&")","Complete") -> Missing (1)
A36: 33 | B36: City Hotel | C36: 0 | D36: 349 | E36: 2016 | F36: October | G36: 41 | H36: 4 | I36: 1 | J36: 5 | K36: 2 | L36: 0 | M36: 0 | N36: BB | O36: DEU | P36: Offline TA/TO | Q36: TA/TO | R36: 0 | S36: 0 | T36: 0 | U36: A | V36: A | W36: 0 | X36: No Deposit | Y36: 58 | AA36: 162 | AB36: Transient-Party | AC36: 123.33 | AD36: 0 | AE36: 0 | AF36: Check-Out | AG36: 42653 | AH36: =B36&"|"&C36&"|"&D36&"|"&E36&"|"&F36&"|"&G36&"|"&H36&"|"&I36&"|"&J36&"|"&K36&"|"&L36&"|"&M36&"|"&N36&"|"&O36&"|"&P36&"|"&Q36&"|"&R36&"|"&S36&"|"&T36&"|"&U36&"|"&V36&"|"&W36&"|"&X36&"|"&Y36&"|"&Z36&"|"&AA36&"|"&AB36&"|"&AC36&"|"&AD36&"|"&AE36&"|"&AF36&"|"&AG36 -> City Hotel|0|349|2016|October|41|4|1|5|2|0|0|BB|DEU|Offline TA/TO|TA/TO|0|0|0|A|A|0|No Deposit|58||162|Transient-Party|123.33|0|0|Check-Out|42653 | AI36: =IF(COUNTIF($AH$4:$AH$2603,AH36)>1,"Duplicate","Unique") -> Unique | AJ36: =IF(COUNTBLANK(B36:AG36)>0,"Missing ("&COUNTBLANK(B36:AG36)&")","Complete") -> Missing (1)
A37: 34 | B37: City Hotel | C37: 0 | D37: 47 | E37: 2016 | F37: February | G37: 8 | H37: 18 | I37: 0 | J37: 3 | K37: 2 | L37: 0 | M37: 0 | N37: BB | O37: NLD | P37: Online TA | Q37: TA/TO | R37: 0 | S37: 0 | T37: 0 | U37: D | V37: D | W37: 0 | X37: No Deposit | Y37: 9 | AA37: 0 | AB37: Transient | AC37: 90.3 | AD37: 0 | AE37: 0 | AF37: Check-Out | AG37: 42421 | AH37: =B37&"|"&C37&"|"&D37&"|"&E37&"|"&F37&"|"&G37&"|"&H37&"|"&I37&"|"&J37&"|"&K37&"|"&L37&"|"&M37&"|"&N37&"|"&O37&"|"&P37&"|"&Q37&"|"&R37&"|"&S37&"|"&T37&"|"&U37&"|"&V37&"|"&W37&"|"&X37&"|"&Y37&"|"&Z37&"|"&AA37&"|"&AB37&"|"&AC37&"|"&AD37&"|"&AE37&"|"&AF37&"|"&AG37 -> City Hotel|0|47|2016|February|8|18|0|3|2|0|0|BB|NLD|Online TA|TA/TO|0|0|0|D|D|0|No Deposit|9||0|Transient|90.3|0|0|Check-Out|42421 | AI37: =IF(COUNTIF($AH$4:$AH$2603,AH37)>1,"Duplicate","Unique") -> Unique | AJ37: =IF(COUNTBLANK(B37:AG37)>0,"Missing ("&COUNTBLANK(B37:AG37)&")","Complete") -> Missing (1)
A38: 35 | B38: City Hotel | C38: 0 | D38: 237 | E38: 2015 | F38: September | G38: 38 | H38: 14 | I38: 1 | J38: 2 | K38: 1 | L38: 0 | M38: 0 | N38: BB | O38: DEU | P38: Online TA | Q38: TA/TO | R38: 0 | S38: 0 | T38: 0 | U38: A | V38: A | W38: 0 | X38: No Deposit | Y38: 9 | AA38: 0 | AB38: Transient-Party | AC38: 80.75 | AD38: 0 | AE38: 0 | AF38: Check-Out | AG38: 42264 | AH38: =B38&"|"&C38&"|"&D38&"|"&E38&"|"&F38&"|"&G38&"|"&H38&"|"&I38&"|"&J38&"|"&K38&"|"&L38&"|"&M38&"|"&N38&"|"&O38&"|"&P38&"|"&Q38&"|"&R38&"|"&S38&"|"&T38&"|"&U38&"|"&V38&"|"&W38&"|"&X38&"|"&Y38&"|"&Z38&"|"&AA38&"|"&AB38&"|"&AC38&"|"&AD38&"|"&AE38&"|"&AF38&"|"&AG38 -> City Hotel|0|237|2015|September|38|14|1|2|1|0|0|BB|DEU|Online TA|TA/TO|0|0|0|A|A|0|No Deposit|9||0|Transient-Party|80.75|0|0|Check-Out|42264 | AI38: =IF(COUNTIF($AH$4:$AH$2603,AH38)>1,"Duplicate","Unique") -> Duplicate | AJ38: =IF(COUNTBLANK(B38:AG38)>0,"Missing ("&COUNTBLANK(B38:AG38)&")","Complete") -> Missing (1)
... A49: 46 | B49: City Hotel | C49: 0 | D49: 7 | E49: 2016 | F49: December | G49: 51 | H49: 17 | I49: 1 | J49: 1 | K49: 2 | L49: 0 | M49: 0 | N49: SC | O49: PRT | P49: Online TA | Q49: TA/TO | R49: 0 | S49: 0 | T49: 0 | U49: A | V49: A | W49: 0 | X49: No Deposit | Y49: 9 | AA49: 0 | AB49: Transient | AC49: 78 | AD49: 0 | AE49: 1 | AF49: Check-Out | AG49: 42723 | AH49: =B49&"|"&C49&"|"&D49&"|"&E49&"|"&F49&"|"&G49&"|"&H49&"|"&I49&"|"&J49&"|"&K49&"|"&L49&"|"&M49&"|"&N49&"|"&O49&"|"&P49&"|"&Q49&"|"&R49&"|"&S49&"|"&T49&"|"&U49&"|"&V49&"|"&W49&"|"&X49&"|"&Y49&"|"&Z49&"|"&AA49&"|"&AB49&"|"&AC49&"|"&AD49&"|"&AE49&"|"&AF49&"|"&AG49 -> City Hotel|0|7|2016|December|51|17|1|1|2|0|0|SC|PRT|Online TA|TA/TO|0|0|0|A|A|0|No Deposit|9||0|Transient|78|0|1|Check-Out|42723 | AI49: =IF(COUNTIF($AH$4:$AH$2603,AH49)>1,"Duplicate","Unique") -> Unique | AJ49: =IF(COUNTBLANK(B49:AG49)>0,"Missing ("&COUNTBLANK(B49:AG49)&")","Complete") -> Missing (1)
A50: 47 | B50: City Hotel | C50: 0 | D50: 21 | E50: 2015 | F50: December | G50: 51 | H50: 17 | I50: 0 | J50: 2 | K50: 1 | L50: 0 | M50: 0 | N50: BB | O50: PRT | P50: Corporate | Q50: Corporate | R50: 0 | S50: 0 | T50: 0 | U50: A | V50: A | W50: 0 | X50: No Deposit | Z50: 40 | AA50: 0 | AB50: Transient-Party | AC50: 65 | AD50: 0 | AE50: 0 | AF50: Check-Out | AG50: 42357 | AH50: =B50&"|"&C50&"|"&D50&"|"&E50&"|"&F50&"|"&G50&"|"&H50&"|"&I50&"|"&J50&"|"&K50&"|"&L50&"|"&M50&"|"&N50&"|"&O50&"|"&P50&"|"&Q50&"|"&R50&"|"&S50&"|"&T50&"|"&U50&"|"&V50&"|"&W50&"|"&X50&"|"&Y50&"|"&Z50&"|"&AA50&"|"&AB50&"|"&AC50&"|"&AD50&"|"&AE50&"|"&AF50&"|"&AG50 -> City Hotel|0|21|2015|December|51|17|0|2|1|0|0|BB|PRT|Corporate|Corporate|0|0|0|A|A|0|No Deposit||40|0|Transient-Party|65|0|0|Check-Out|42357 | AI50: =IF(COUNTIF($AH$4:$AH$2603,AH50)>1,"Duplicate","Unique") -> Unique | AJ50: =IF(COUNTBLANK(B50:AG50)>0,"Missing ("&COUNTBLANK(B50:AG50)&")","Complete") -> Missing (1)
...

Sheet Cleaning Log
B2: DATA CLEANING LOG
B4: Issue Found | C4: Action Taken (manual Excel steps) | D4: Rows Affected
B5: Duplicate booking records | C5: Selected the full table -> Data tab -> Remove Duplicates (all columns except Booking ID). Verified count first using the Duplicate Check formula on the 'Raw Data' sheet. | D5: =COUNTIF('Raw Data'!$AI$4:$AI$2603,"Duplicate") -> 257
B6: Missing 'Country' values | C6: Used Find & Replace (Ctrl+H) on blanks -> replaced with "Unknown" so the field can still be grouped in PivotTables/Power BI. | D6: =COUNTBLANK('Raw Data'!O:O) -> 1045986
B7: Missing 'Agent' / 'Company' ID | C7: These are legitimately blank when a booking was not made through a travel agent or company (not an error). Replaced blanks with 0 so numeric aggregation formulas do not break. | D7: =COUNTBLANK('Raw Data'!Y:Y)+COUNTBLANK('Raw Data'!Z:Z) -> 2094759
B8: Missing 'Children' values | C8: Replaced blanks with 0 (assumes no children where unspecified). | D8: =COUNTBLANK('Raw Data'!L:L) -> 1045975
B9: Bookings with 0 total guests | C9: 3 rows had 0 adults, 0 children and 0 babies — a logical impossibility. Deleted these rows entirely. | D9: 3
B10: Data type formatting | C10: Confirmed all date fields are stored as genuine Excel dates (not text) and all numeric fields (ADR, lead time, nights) are stored as Number, not Text, so formulas/PivotTables total correctly. | D10: All rows
B13: BEFORE / AFTER SUMMARY
B14: Rows before cleaning | C14: =COUNTA('Raw Data'!A4:A2603) -> 2600
B15: Duplicate rows removed (net) | C15: 146
B16: Zero-guest rows removed | C16: 3
B17: Rows after cleaning (see 'Cleaned Data' sheet) | C17: =COUNTA('Cleaned Data'!A4:A2454) -> 2451

Sheet Cleaned Data
A1: CLEANED DATA + CALCULATED COLUMNS (2,451 bookings)
A3: booking_id | B3: hotel | C3: is_canceled | D3: lead_time | E3: arrival_date_year | F3: arrival_date_month | G3: arrival_date_week_number | H3: arrival_date_day_of_month | I3: stays_in_weekend_nights | J3: stays_in_week_nights | K3: adults | L3: children | M3: babies | N3: meal | O3: country | P3: market_segment | Q3: distribution_channel | R3: is_repeated_guest | S3: previous_cancellations | T3: previous_bookings_not_canceled | U3: reserved_room_type | V3: assigned_room_type | W3: booking_changes | X3: deposit_type | Y3: agent | Z3: company | AA3: days_in_waiting_list | AB3: customer_type | AC3: adr | AD3: required_car_parking_spaces | AE3: total_of_special_requests | AF3: reservation_status | AG3: reservation_status_date | AH3: Total Nights | AI3: Total Guests | AJ3: Total Revenue | AK3: Booking Status | AL3: Lead Time Bucket | AM3: Season | AN3: Guest Type | AO3: Room Match
A4: 1 | B4: Resort Hotel | C4: 0 | D4: 203 | E4: 2016 | F4: December | G4: 49 | H4: 2 | I4: 2 | J4: 5 | K4: 2 | L4: 0 | M4: 0 | N4: BB | O4: GBR | P4: Direct | Q4: Direct | R4: 0 | S4: 0 | T4: 0 | U4: F | V4: F | W4: 4 | X4: No Deposit | Y4: 250 | Z4: 0 | AA4: 0 | AB4: Transient | AC4: 66.8 | AD4: 0 | AE4: 0 | AF4: Check-Out | AG4: 42713 | AH4: =I4+J4 -> 7 | AI4: =K4+L4+M4 -> 2 | AJ4: =AC4*AH4 -> 467.6 | AK4: =IF(C4=1,"Cancelled","Completed") -> Completed | AL4: =_xlfn.IFS(D4<=7,"0-7 Days",D4<=30,"8-30 Days",D4<=90,"31-90 Days",TRUE(),"90+ Days") -> 90+ Days | AM4: =_xlfn.IFS(OR(F4="December",F4="January",F4="February"),"Winter",OR(F4="March",F4="April",F4="May"),"Spring",OR(F4="June",F4="July",F4="August"),"Summer",TRUE(),"Autumn") -> Winter | AN4: =IF(L4+M4>0,"Family","Adult Only") -> Adult Only | AO4: =IF(U4=V4,"Same","Changed") -> Same
A5: 2 | B5: City Hotel | C5: 1 | D5: 82 | E5: 2015 | F5: July | G5: 29 | H5: 16 | I5: 0 | J5: 3 | K5: 2 | L5: 0 | M5: 0 | N5: BB | O5: PRT | P5: Online TA | Q5: TA/TO | R5: 0 | S5: 0 | T5: 0 | U5: A | V5: A | W5: 0 | X5: No Deposit | Y5: 9 | Z5: 0 | AA5: 0 | AB5: Transient | AC5: 76.5 | AD5: 0 | AE5: 0 | AF5: Canceled | AG5: 42201 | AH5: =I5+J5 -> 3 | AI5: =K5+L5+M5 -> 2 | AJ5: =AC5*AH5 -> 229.5 | AK5: =IF(C5=1,"Cancelled","Completed") -> Cancelled | AL5: =_xlfn.IFS(D5<=7,"0-7 Days",D5<=30,"8-30 Days",D5<=90,"31-90 Days",TRUE(),"90+ Days") -> 31-90 Days | AM5: =_xlfn.IFS(OR(F5="December",F5="January",F5="February"),"Winter",OR(F5="March",F5="April",F5="May"),"Spring",OR(F5="June",F5="July",F5="August"),"Summer",TRUE(),"Autumn") -> Summer | AN5: =IF(L5+M5>0,"Family","Adult Only") -> Adult Only | AO5: =IF(U5=V5,"Same","Changed") -> Same
A6: 3 | B6: City Hotel | C6: 0 | D6: 25 | E6: 2016 | F6: December | G6: 53 | H6: 27 | I6: 0 | J6: 3 | K6: 3 | L6: 0 | M6: 0 | N6: BB | O6: BRA | P6: Offline TA/TO | Q6: TA/TO | R6: 0 | S6: 0 | T6: 0 | U6: A | V6: K | W6: 2 | X6: No Deposit | Y6: 220 | Z6: 0 | AA6: 0 | AB6: Transient-Party | AC6: 60 | AD6: 0 | AE6: 1 | AF6: Check-Out | AG6: 42734 | AH6: =I6+J6 -> 3 | AI6: =K6+L6+M6 -> 3 | AJ6: =AC6*AH6 -> 180 | AK6: =IF(C6=1,"Cancelled","Completed") -> Completed | AL6: =_xlfn.IFS(D6<=7,"0-7 Days",D6<=30,"8-30 Days",D6<=90,"31-90 Days",TRUE(),"90+ Days") -> 8-30 Days | AM6: =_xlfn.IFS(OR(F6="December",F6="January",F6="February"),"Winter",OR(F6="March",F6="April",F6="May"),"Spring",OR(F6="June",F6="July",F6="August"),"Summer",TRUE(),"Autumn") -> Winter | AN6: =IF(L6+M6>0,"Family","Adult Only") -> Adult Only | AO6: =IF(U6=V6,"Same","Changed") -> Changed
A7: 4 | B7: City Hotel | C7: 0 | D7: 1 | E7: 2016 | F7: March | G7: 11 | H7: 9 | I7: 0 | J7: 1 | K7: 1 | L7: 0 | M7: 0 | N7: BB | O7: SWE | P7: Online TA | Q7: TA/TO | R7: 0 | S7: 0 | T7: 0 | U7: A | V7: A | W7: 0 | X7: No Deposit | Y7: 9 | Z7: 0 | AA7: 0 | AB7: Transient-Party | AC7: 95 | AD7: 0 | AE7: 0 | AF7: Check-Out | AG7: 42439 | AH7: =I7+J7 -> 1 | AI7: =K7+L7+M7 -> 1 | AJ7: =AC7*AH7 -> 95 | AK7: =IF(C7=1,"Cancelled","Completed") -> Completed | AL7: =_xlfn.IFS(D7<=7,"0-7 Days",D7<=30,"8-30 Days",D7<=90,"31-90 Days",TRUE(),"90+ Days") -> 0-7 Days | AM7: =_xlfn.IFS(OR(F7="December",F7="January",F7="February"),"Winter",OR(F7="March",F7="April",F7="May"),"Spring",OR(F7="June",F7="July",F7="August"),"Summer",TRUE(),"Autumn") -> Spring | AN7: =IF(L7+M7>0,"Family","Adult Only") -> Adult Only | AO7: =IF(U7=V7,"Same","Changed") -> Same
A8: 5 | B8: City Hotel | C8: 0 | D8: 70 | E8: 2017 | F8: April | G8: 16 | H8: 16 | I8: 2 | J8: 2 | K8: 2 | L8: 0 | M8: 0 | N8: SC | O8: GBR | P8: Online TA | Q8: TA/TO | R8: 0 | S8: 0 | T8: 0 | U8: A | V8: A | W8: 0 | X8: No Deposit | Y8: 9 | Z8: 0 | AA8: 0 | AB8: Transient | AC8: 108 | AD8: 0 | AE8: 0 | AF8: Check-Out | AG8: 42845 | AH8: =I8+J8 -> 4 | AI8: =K8+L8+M8 -> 2 | AJ8: =AC8*AH8 -> 432 | AK8: =IF(C8=1,"Cancelled","Completed") -> Completed | AL8: =_xlfn.IFS(D8<=7,"0-7 Days",D8<=30,"8-30 Days",D8<=90,"31-90 Days",TRUE(),"90+ Days") -> 31-90 Days | AM8: =_xlfn.IFS(OR(F8="December",F8="January",F8="February"),"Winter",OR(F8="March",F8="April",F8="May"),"Spring",OR(F8="June",F8="July",F8="August"),"Summer",TRUE(),"Autumn") -> Spring | AN8: =IF(L8+M8>0,"Family","Adult Only") -> Adult Only | AO8: =IF(U8=V8,"Same","Changed") -> Same
A9: 6 | B9: City Hotel | C9: 0 | D9: 170 | E9: 2017 | F9: April | G9: 17 | H9: 27 | I9: 0 | J9: 3 | K9: 2 | L9: 0 | M9: 0 | N9: BB | O9: DEU | P9: Online TA | Q9: TA/TO | R9: 0 | S9: 0 | T9: 0 | U9: D | V9: D | W9: 0 | X9: No Deposit | Y9: 9 | Z9: 0 | AA9: 0 | AB9: Transient | AC9: 130.5 | AD9: 0 | AE9: 0 | AF9: Check-Out | AG9: 42855 | AH9: =I9+J9 -> 3 | AI9: =K9+L9+M9 -> 2 | AJ9: =AC9*AH9 -> 391.5 | AK9: =IF(C9=1,"Cancelled","Completed") -> Completed | AL9: =_xlfn.IFS(D9<=7,"0-7 Days",D9<=30,"8-30 Days",D9<=90,"31-90 Days",TRUE(),"90+ Days") -> 90+ Days | AM9: =_xlfn.IFS(OR(F9="December",F9="January",F9="February"),"Winter",OR(F9="March",F9="April",F9="May"),"Spring",OR(F9="June",F9="July",F9="August"),"Summer",TRUE(),"Autumn") -> Spring | AN9: =IF(L9+M9>0,"Family","Adult Only") -> Adult Only | AO9: =IF(U9=V9,"Same","Changed") -> Same
A10: 7 | B10: City Hotel | C10: 1 | D10: 21 | E10: 2016 | F10: March | G10: 10 | H10: 4 | I10: 0 | J10: 1 | K10: 1 | L10: 0 | M10: 0 | N10: BB | O10: SVN | P10: Online TA | Q10: TA/TO | R10: 0 | S10: 0 | T10: 0 | U10: A | V10: A | W10: 0 | X10: No Deposit | Y10: 9 | Z10: 0 | AA10: 0 | AB10: Transient-Party | AC10: 85 | AD10: 0 | AE10: 0 | AF10: Canceled | AG10: 42426 | AH10: =I10+J10 -> 1 | AI10: =K10+L10+M10 -> 1 | AJ10: =AC10*AH10 -> 85 | AK10: =IF(C10=1,"Cancelled","Completed") -> Cancelled | AL10: =_xlfn.IFS(D10<=7,"0-7 Days",D10<=30,"8-30 Days",D10<=90,"31-90 Days",TRUE(),"90+ Days") -> 8-30 Days | AM10: =_xlfn.IFS(OR(F10="December",F10="January",F10="February"),"Winter",OR(F10="March",F10="April",F10="May"),"Spring",OR(F10="June",F10="July",F10="August"),"Summer",TRUE(),"Autumn") -> Spring | AN10: =IF(L10+M10>0,"Family","Adult Only") -> Adult Only | AO10: =IF(U10=V10,"Same","Changed") -> Same
A11: 8 | B11: City Hotel | C11: 0 | D11: 102 | E11: 2015 | F11: October | G11: 42 | H11: 16 | I11: 0 | J11: 2 | K11: 2 | L11: 0 | M11: 0 | N11: HB | O11: DEU | P11: Offline TA/TO | Q11: TA/TO | R11: 0 | S11: 0 | T11: 0 | U11: A | V11: D | W11: 0 | X11: No Deposit | Y11: 6 | Z11: 0 | AA11: 0 | AB11: Transient-Party | AC11: 109 | AD11: 0 | AE11: 0 | AF11: Check-Out | AG11: 42295 | AH11: =I11+J11 -> 2 | AI11: =K11+L11+M11 -> 2 | AJ11: =AC11*AH11 -> 218 | AK11: =IF(C11=1,"Cancelled","Completed") -> Completed | AL11: =_xlfn.IFS(D11<=7,"0-7 Days",D11<=30,"8-30 Days",D11<=90,"31-90 Days",TRUE(),"90+ Days") -> 90+ Days | AM11: =_xlfn.IFS(OR(F11="December",F11="January",F11="February"),"Winter",OR(F11="March",F11="April",F11="May"),"Spring",OR(F11="June",F11="July",F11="August"),"Summer",TRUE(),"Autumn") -> Autumn | AN11: =IF(L11+M11>0,"Family","Adult Only") -> Adult Only | AO11: =IF(U11=V11,"Same","Changed") -> Changed
A12: 9 | B12: Resort Hotel | C12: 0 | D12: 55 | E12: 2016 | F12: November | G12: 47 | H12: 19 | I12: 2 | J12: 5 | K12: 2 | L12: 0 | M12: 0 | N12: HB | O12: GBR | P12: Online TA | Q12: TA/TO | R12: 0 | S12: 0 | T12: 0 | U12: D | V12: D | W12: 1 | X12: No Deposit | Y12: 314 | Z12: 0 | AA12: 0 | AB12: Transient | AC12: 67.44 | AD12: 0 | AE12: 0 | AF12: Check-Out | AG12: 42700 | AH12: =I12+J12 -> 7 | AI12: =K12+L12+M12 -> 2 | AJ12: =AC12*AH12 -> 472.08 | AK12: =IF(C12=1,"Cancelled","Completed") -> Completed | AL12: =_xlfn.IFS(D12<=7,"0-7 Days",D12<=30,"8-30 Days",D12<=90,"31-90 Days",TRUE(),"90+ Days") -> 31-90 Days | AM12: =_xlfn.IFS(OR(F12="December",F12="January",F12="February"),"Winter",OR(F12="March",F12="April",F12="May"),"Spring",OR(F12="June",F12="July",F12="August"),"Summer",TRUE(),"Autumn") -> Autumn | AN12: =IF(L12+M12>0,"Family","Adult Only") -> Adult Only | AO12: =IF(U12=V12,"Same","Changed") -> Same
A13: 10 | B13: Resort Hotel | C13: 0 | D13: 222 | E13: 2015 | F13: September | G13: 38 | H13: 14 | I13: 1 | J13: 1 | K13: 2 | L13: 0 | M13: 0 | N13: HB | O13: ESP | P13: Groups | Q13: TA/TO | R13: 0 | S13: 0 | T13: 0 | U13: A | V13: A | W13: 0 | X13: No Deposit | Y13: 68 | Z13: 0 | AA13: 0 | AB13: Transient | AC13: 80 | AD13: 0 | AE13: 0 | AF13: Check-Out | AG13: 42263 | AH13: =I13+J13 -> 2 | AI13: =K13+L13+M13 -> 2 | AJ13: =AC13*AH13 -> 160 | AK13: =IF(C13=1,"Cancelled","Completed") -> Completed | AL13: =_xlfn.IFS(D13<=7,"0-7 Days",D13<=30,"8-30 Days",D13<=90,"31-90 Days",TRUE(),"90+ Days") -> 90+ Days | AM13: =_xlfn.IFS(OR(F13="December",F13="January",F13="February"),"Winter",OR(F13="March",F13="April",F13="May"),"Spring",OR(F13="June",F13="July",F13="August"),"Summer",TRUE(),"Autumn") -> Autumn | AN13: =IF(L13+M13>0,"Family","Adult Only") -> Adult Only | AO13: =IF(U13=V13,"Same","Changed") -> Same
A14: 11 | B14: Resort Hotel | C14: 0 | D14: 120 | E14: 2016 | F14: December | G14: 53 | H14: 26 | I14: 1 | J14: 3 | K14: 2 | L14: 0 | M14: 0 | N14: BB | O14: BEL | P14: Online TA | Q14: TA/TO | R14: 0 | S14: 0 | T14: 0 | U14: D | V14: D | W14: 0 | X14: No Deposit | Y14: 240 | Z14: 0 | AA14: 0 | AB14: Transient-Party | AC14: 54.8 | AD14: 1 | AE14: 3 | AF14: Check-Out | AG14: 42734 | AH14: =I14+J14 -> 4 | AI14: =K14+L14+M14 -> 2 | AJ14: =AC14*AH14 -> 219.2 | AK14: =IF(C14=1,"Cancelled","Completed") -> Completed | AL14: =_xlfn.IFS(D14<=7,"0-7 Days",D14<=30,"8-30 Days",D14<=90,"31-90 Days",TRUE(),"90+ Days") -> 90+ Days | AM14: =_xlfn.IFS(OR(F14="December",F14="January",F14="February"),"Winter",OR(F14="March",F14="April",F14="May"),"Spring",OR(F14="June",F14="July",F14="August"),"Summer",TRUE(),"Autumn") -> Winter | AN14: =IF(L14+M14>0,"Family","Adult Only") -> Adult Only | AO14: =IF(U14=V14,"Same","Changed") -> Same
A15: 12 | B15: City Hotel | C15: 1 | D15: 88 | E15: 2017 | F15: February | G15: 7 | H15: 17 | I15: 0 | J15: 2 | K15: 2 | L15: 0 | M15: 0 | N15: SC | O15: DEU | P15: Online TA | Q15: TA/TO | R15: 0 | S15: 0 | T15: 0 | U15: A | V15: A | W15: 0 | X15: No Deposit | Y15: 9 | Z15: 0 | AA15: 0 | AB15: Transient | AC15: 79.2 | AD15: 0 | AE15: 0 | AF15: Canceled | AG15: 42699 | AH15: =I15+J15 -> 2 | AI15: =K15+L15+M15 -> 2 | AJ15: =AC15*AH15 -> 158.4 | AK15: =IF(C15=1,"Cancelled","Completed") -> Cancelled | AL15: =_xlfn.IFS(D15<=7,"0-7 Days",D15<=30,"8-30 Days",D15<=90,"31-90 Days",TRUE(),"90+ Days") -> 31-90 Days | AM15: =_xlfn.IFS(OR(F15="December",F15="January",F15="February"),"Winter",OR(F15="March",F15="April",F15="May"),"Spring",OR(F15="June",F15="July",F15="August"),"Summer",TRUE(),"Autumn") -> Winter | AN15: =IF(L15+M15>0,"Family","Adult Only") -> Adult Only | AO15: =IF(U15=V15,"Same","Changed") -> Same
... A2454: 2600 | B2454: City Hotel | C2454: 1 | D2454: 50 | E2454: 2015 | F2454: October | G2454: 43 | H2454: 24 | I2454: 0 | J2454: 1 | K2454: 2 | L2454: 0 | M2454: 0 | N2454: HB | O2454: PRT | P2454: Groups | Q2454: TA/TO | R2454: 0 | S2454: 0 | T2454: 0 | U2454: A | V2454: A | W2454: 0 | X2454: Non Refund | Y2454: 0 | Z2454: 0 | AA2454: 0 | AB2454: Transient | AC2454: 146 | AD2454: 0 | AE2454: 0 | AF2454: Canceled | AG2454: 42292 | AH2454: =I2454+J2454 -> 1 | AI2454: =K2454+L2454+M2454 -> 2 | AJ2454: =AC2454*AH2454 -> 146 | AK2454: =IF(C2454=1,"Cancelled","Completed") -> Cancelled | AL2454: =_xlfn.IFS(D2454<=7,"0-7 Days",D2454<=30,"8-30 Days",D2454<=90,"31-90 Days",TRUE(),"90+ Days") -> 31-90 Days | AM2454: =_xlfn.IFS(OR(F2454="December",F2454="January",F2454="February"),"Winter",OR(F2454="March",F2454="April",F2454="May"),"Spring",OR(F2454="June",F2454="July",F2454="August"),"Summer",TRUE(),"Autumn") -> Autumn | AN2454: =IF(L2454+M2454>0,"Family","Adult Only") -> Adult Only | AO2454: =IF(U2454=V2454,"Same","Changed") -> Same
A2456: CALCULATED COLUMN FORMULA REFERENCE
A2457: Total Nights | B2457: Weekend nights + Week nights
A2458: Total Guests | B2458: Adults + Children + Babies
A2459: Total Revenue | B2459: ADR (Average Daily Rate) x Total Nights
A2460: Booking Status | B2460: IF(is_canceled=1,"Cancelled","Completed")
A2461: Lead Time Bucket | B2461: IFS: 0-7 / 8-30 / 31-90 / 90+ days between booking and arrival
A2462: Season | B2462: Grouped from arrival month (Winter/Spring/Summer/Autumn)
A2463: Guest Type | B2463: IF(children+babies>0,"Family","Adult Only")
A2464: Room Match | B2464: Compares Reserved vs Assigned room type - flags operational reassignments

Sheet KPI Dashboard
B2: HOTEL BOOKING ANALYSIS — KPI DASHBOARD
B3: All figures calculated live from the 'Cleaned Data' sheet (2,451-row sample) using SUMIFS/COUNTIFS/AVERAGEIFS formulas. This sample happens to contain a slightly higher share of cancelled bookings than the full dataset (36% vs 27.5%) — see 'Key Findings & Business Recommendations.docx' for headline KPIs computed on the full 87,230-row cleaned dataset.
B5: Total Bookings | D5: Cancelled Bookings | F5: Cancellation Rate | H5: Total Revenue (Completed)
B6: =COUNTA('Cleaned Data'!$A$4:$A$2454) -> 2451 | D6: =COUNTIF('Cleaned Data'!$C$4:$C$2454,1) -> 887 | F6: =COUNTIF('Cleaned Data'!$C$4:$C$2454,1)/COUNTA('Cleaned Data'!$A$4:$A$2454) -> 0.3618931 | H6: =SUMIFS('Cleaned Data'!$AJ$4:$AJ$2454,'Cleaned Data'!$C$4:$C$2454,0) -> 533753.22
B8: Average Daily Rate (ADR) | D8: Average Lead Time (days) | F8: Average Stay (nights) | H8: Repeat Guest Rate
B9: =AVERAGE('Cleaned Data'!$AC$4:$AC$2454) -> 102.56952 | D9: =AVERAGE('Cleaned Data'!$D$4:$D$2454) -> 99.873113 | F9: =AVERAGE('Cleaned Data'!$AH$4:$AH$2454) -> 3.4128927 | H9: =COUNTIF('Cleaned Data'!$R$4:$R$2454,1)/COUNTA('Cleaned Data'!$A$4:$A$2454) -> 0.027743778
B12: Hotel Type | C12: Bookings | D12: Cancel Rate | E12: Revenue
B13: City Hotel | C13: =COUNTIF('Cleaned Data'!$B$4:$B$2454,B13) -> 1553 | D13: =COUNTIFS('Cleaned Data'!$B$4:$B$2454,B13,'Cleaned Data'!$C$4:$C$2454,1)/COUNTIF('Cleaned Data'!$B$4:$B$2454,B13) -> 0.40051513 | E13: =SUMIFS('Cleaned Data'!$AJ$4:$AJ$2454,'Cleaned Data'!$B$4:$B$2454,B13,'Cleaned Data'!$C$4:$C$2454,0) -> 289666.32
B14: Resort Hotel | C14: =COUNTIF('Cleaned Data'!$B$4:$B$2454,B14) -> 898 | D14: =COUNTIFS('Cleaned Data'!$B$4:$B$2454,B14,'Cleaned Data'!$C$4:$C$2454,1)/COUNTIF('Cleaned Data'!$B$4:$B$2454,B14) -> 0.29510022 | E14: =SUMIFS('Cleaned Data'!$AJ$4:$AJ$2454,'Cleaned Data'!$B$4:$B$2454,B14,'Cleaned Data'!$C$4:$C$2454,0) -> 244086.9
B17: Booking Status | C17: Count
B18: Completed | C18: =COUNTIF('Cleaned Data'!$C$4:$C$2454,0) -> 1564
B19: Cancelled | C19: =COUNTIF('Cleaned Data'!$C$4:$C$2454,1) -> 887

Sheet Pivot - Cancellation
A1: CANCELLATION ANALYSIS
A3: By Hotel Type
A4: Category | B4: Bookings | C4: Cancelled | D4: Cancel Rate | E4: Total Revenue | F4: Avg ADR | G4: Avg Lead Time | H4: Avg Nights
A5: City Hotel | B5: =COUNTIF('Cleaned Data'!$B$4:$B$2454,A5) -> 1553 | C5: =COUNTIFS('Cleaned Data'!$B$4:$B$2454,A5,'Cleaned Data'!$C$4:$C$2454,1) -> 622 | D5: =IF(A5="","",C5/B5) -> 0.40051513 | E5: =SUMIFS('Cleaned Data'!$AJ$4:$AJ$2454,'Cleaned Data'!$B$4:$B$2454,A5,'Cleaned Data'!$C$4:$C$2454,0) -> 289666.32 | F5: =AVERAGEIFS('Cleaned Data'!$AC$4:$AC$2454,'Cleaned Data'!$B$4:$B$2454,A5) -> 106.11897 | G5: =AVERAGEIFS('Cleaned Data'!$D$4:$D$2454,'Cleaned Data'!$B$4:$B$2454,A5) -> 104.0586 | H5: =AVERAGEIFS('Cleaned Data'!$AH$4:$AH$2454,'Cleaned Data'!$B$4:$B$2454,A5) -> 2.9523503
A6: Resort Hotel | B6: =COUNTIF('Cleaned Data'!$B$4:$B$2454,A6) -> 898 | C6: =COUNTIFS('Cleaned Data'!$B$4:$B$2454,A6,'Cleaned Data'!$C$4:$C$2454,1) -> 265 | D6: =IF(A6="","",C6/B6) -> 0.29510022 | E6: =SUMIFS('Cleaned Data'!$AJ$4:$AJ$2454,'Cleaned Data'!$B$4:$B$2454,A6,'Cleaned Data'!$C$4:$C$2454,0) -> 244086.9 | F6: =AVERAGEIFS('Cleaned Data'!$AC$4:$AC$2454,'Cleaned Data'!$B$4:$B$2454,A6) -> 96.431102 | G6: =AVERAGEIFS('Cleaned Data'!$D$4:$D$2454,'Cleaned Data'!$B$4:$B$2454,A6) -> 92.634744 | H6: =AVERAGEIFS('Cleaned Data'!$AH$4:$AH$2454,'Cleaned Data'!$B$4:$B$2454,A6) -> 4.2093541
A8: By Lead Time Bucket
A9: Category | B9: Bookings | C9: Cancelled | D9: Cancel Rate | E9: Total Revenue | F9: Avg ADR | G9: Avg Lead Time | H9: Avg Nights
A10: 0-7 Days | B10: =COUNTIF('Cleaned Data'!$AL$4:$AL$2454,A10) -> 427 | C10: =COUNTIFS('Cleaned Data'!$AL$4:$AL$2454,A10,'Cleaned Data'!$C$4:$C$2454,1) -> 43 | D10: =IF(A10="","",C10/B10) -> 0.10070258 | E10: =SUMIFS('Cleaned Data'!$AJ$4:$AJ$2454,'Cleaned Data'!$AL$4:$AL$2454,A10,'Cleaned Data'!$C$4:$C$2454,0) -> 73001.81 | F10: =AVERAGEIFS('Cleaned Data'!$AC$4:$AC$2454,'Cleaned Data'!$AL$4:$AL$2454,A10) -> 93.462857 | G10: =AVERAGEIFS('Cleaned Data'!$D$4:$D$2454,'Cleaned Data'!$AL$4:$AL$2454,A10) -> 2.4637002 | H10: =AVERAGEIFS('Cleaned Data'!$AH$4:$AH$2454,'Cleaned Data'!$AL$4:$AL$2454,A10) -> 2.028103
A11: 8-30 Days | B11: =COUNTIF('Cleaned Data'!$AL$4:$AL$2454,A11) -> 388 | C11: =COUNTIFS('Cleaned Data'!$AL$4:$AL$2454,A11,'Cleaned Data'!$C$4:$C$2454,1) -> 112 | D11: =IF(A11="","",C11/B11) -> 0.28865979 | E11: =SUMIFS('Cleaned Data'!$AJ$4:$AJ$2454,'Cleaned Data'!$AL$4:$AL$2454,A11,'Cleaned Data'!$C$4:$C$2454,0) -> 85199.21 | F11: =AVERAGEIFS('Cleaned Data'!$AC$4:$AC$2454,'Cleaned Data'!$AL$4:$AL$2454,A11) -> 107.58786 | G11: =AVERAGEIFS('Cleaned Data'!$D$4:$D$2454,'Cleaned Data'!$AL$4:$AL$2454,A11) -> 18.087629 | H11: =AVERAGEIFS('Cleaned Data'!$AH$4:$AH$2454,'Cleaned Data'!$AL$4:$AL$2454,A11) -> 2.8427835
A12: 31-90 Days | B12: =COUNTIF('Cleaned Data'!$AL$4:$AL$2454,A12) -> 623 | C12: =COUNTIFS('Cleaned Data'!$AL$4:$AL$2454,A12,'Cleaned Data'!$C$4:$C$2454,1) -> 217 | D12: =IF(A12="","",C12/B12) -> 0.34831461 | E12: =SUMIFS('Cleaned Data'!$AJ$4:$AJ$2454,'Cleaned Data'!$AL$4:$AL$2454,A12,'Cleaned Data'!$C$4:$C$2454,0) -> 150860.17 | F12: =AVERAGEIFS('Cleaned Data'!$AC$4:$AC$2454,'Cleaned Data'!$AL$4:$AL$2454,A12) -> 107.64579 | G12: =AVERAGEIFS('Cleaned Data'!$D$4:$D$2454,'Cleaned Data'!$AL$4:$AL$2454,A12) -> 56.805778 | H12: =AVERAGEIFS('Cleaned Data'!$AH$4:$AH$2454,'Cleaned Data'!$AL$4:$AL$2454,A12) -> 3.6998395
A13: 90+ Days | B13: =COUNTIF('Cleaned Data'!$AL$4:$AL$2454,A13) -> 1013 | C13: =COUNTIFS('Cleaned Data'!$AL$4:$AL$2454,A13,'Cleaned Data'!$C$4:$C$2454,1) -> 515 | D13: =IF(A13="","",C13/B13) -> 0.50839092 | E13: =SUMIFS('Cleaned Data'!$AJ$4:$AJ$2454,'Cleaned Data'!$AL$4:$AL$2454,A13,'Cleaned Data'!$C$4:$C$2454,0) -> 224692.03 | F13: =AVERAGEIFS('Cleaned Data'!$AC$4:$AC$2454,'Cleaned Data'!$AL$4:$AL$2454,A13) -> 101.3641 | G13: =AVERAGEIFS('Cleaned Data'!$D$4:$D$2454,'Cleaned Data'!$AL$4:$AL$2454,A13) -> 198.74531 | H13: =AVERAGEIFS('Cleaned Data'!$AH$4:$AH$2454,'Cleaned Data'!$AL$4:$AL$2454,A13) -> 4.0384995
A15: By Deposit Type
